Workbook
Name PriceTable: Data!$A$2:$C$6
Name TaxRate: Data!$F$1

Sheet Summary
A1: Category | B1: Cases | C1: OK | D1: Fails
A2: Operators | B2: 33 | C2: =COUNTIF('Operators'!$E$2:$E$34,"OK") | D2: =B2-C2
A3: Math | B3: 61 | C3: =COUNTIF('Math'!$E$2:$E$62,"OK") | D3: =B3-C3
A4: Text | B4: 55 | C4: =COUNTIF('Text'!$E$2:$E$56,"OK") | D4: =B4-C4
A5: Logical | B5: 19 | C5: =COUNTIF('Logical'!$E$2:$E$20,"OK") | D5: =B5-C5
A6: Lookup | B6: 40 | C6: =COUNTIF('Lookup'!$E$2:$E$41,"OK") | D6: =B6-C6
A7: Dates | B7: 28 | C7: =COUNTIF('Dates'!$E$2:$E$29,"OK") | D7: =B7-C7
A8: Stats | B8: 27 | C8: =COUNTIF('Stats'!$E$2:$E$28,"OK") | D8: =B8-C8
A9: Info | B9: 19 | C9: =COUNTIF('Info'!$E$2:$E$20,"OK") | D9: =B9-C9
A10: Financial | B10: 12 | C10: =COUNTIF('Financial'!$E$2:$E$13,"OK") | D10: =B10-C10
A11: Engineering | B11: 22 | C11: =COUNTIF('Engineering'!$E$2:$E$23,"OK") | D11: =B11-C11
A12: Database | B12: 5 | C12: =COUNTIF('Database'!$E$2:$E$6,"OK") | D12: =B12-C12
A13: Errors | B13: 6 | C13: =COUNTIF('Errors'!$E$2:$E$7,"OK") | D13: =B13-C13
A14: Gaps | B14: 4 | C14: =COUNTIF('Gaps'!$E$2:$E$5,"OK") | D14: =B14-C14
A15: TOTAL | B15: =SUM(B2:B14) | C15: =SUM(C2:C14) | D15: =SUM(D2:D14)
A17: =IF(D15=0,"ALL PASS",D15&" FAILURES")

Sheet Data
A1: Fruit | B1: Qty | C1: Price | E1: 5 | F1: 0.15 | G1: text | H1: Hello World | J1: =1+1 | K1: a | L1: b | M1: c | O1: -100
A2: Apple | B2: 10 | C2: 0.5 | E2: 3 | G2: 42 | H2: padded | K2: 1 | L2: 2 | M2: 3 | O2: 110
A3: Banana | B3: 20 | C3: 0.25 | E3: 8 | F3: 10 | G3: TRUE | H3: MiXeD cAsE
A4: Cherry | B4: 5 | C4: 3.2 | E4: 1 | F4: 20 | K4: Qty | L4: Fruit
A5: Date | B5: 15 | C5: 4.5 | E5: 9 | F5: 30 | G5: =NA() | K5: >8 | L5: Date
A6: Elderberry | B6: 8 | C6: 7 | E6: 2 | F6: 40
E7: 7 | F7: 50
E8: 4

Sheet Operators
A1: ID | B1: Note | C1: Actual | D1: Expected | E1: Check
A2: OPE001 | B2: precedence: * before + | C2: =2+3*4 | D2: 14 | E2: =IF(ISNUMBER(C2),IF(ABS(C2-D2)<0.000000001,"OK","FAIL"),"FAIL")
A3: OPE002 | B3: parens | C3: =(2+3)*4 | D3: 20 | E3: =IF(ISNUMBER(C3),IF(ABS(C3-D3)<0.000000001,"OK","FAIL"),"FAIL")
A4: OPE003 | B4: ^ is LEFT-associative in Excel: (2^3)^2 | C4: =2^3^2 | D4: 64 | E4: =IF(ISNUMBER(C4),IF(ABS(C4-D4)<0.000000001,"OK","FAIL"),"FAIL")
A5: OPE004 | B5: unary minus binds tighter than ^: (-2)^2 | C5: =-2^2 | D5: 4 | E5: =IF(ISNUMBER(C5),IF(ABS(C5-D5)<0.000000001,"OK","FAIL"),"FAIL")
A6: OPE005 | B6: negative exponent | C6: =2^-2 | D6: 0.25 | E6: =IF(ISNUMBER(C6),IF(ABS(C6-D6)<0.000000001,"OK","FAIL"),"FAIL")
A7: OPE006 | B7: percent literal | C7: =50% | D7: 0.5 | E7: =IF(ISNUMBER(C7),IF(ABS(C7-D7)<0.000000001,"OK","FAIL"),"FAIL")
A8: OPE007 | B8: percent arithmetic | C8: =50%+50% | D8: 1 | E8: =IF(ISNUMBER(C8),IF(ABS(C8-D8)<0.000000001,"OK","FAIL"),"FAIL")
A9: OPE008 | C9: =10%*10 | D9: 1 | E9: =IF(ISNUMBER(C9),IF(ABS(C9-D9)<0.000000001,"OK","FAIL"),"FAIL")
A10: OPE009 | B10: true division | C10: =5/2 | D10: 2.5 | E10: =IF(ISNUMBER(C10),IF(ABS(C10-D10)<0.000000001,"OK","FAIL"),"FAIL")
A11: OPE010 | B11: fp addition within epsilon | C11: =0.1+0.2 | D11: 0.3 | E11: =IF(ISNUMBER(C11),IF(ABS(C11-D11)<0.000000001,"OK","FAIL"),"FAIL")
A12: OPE011 | B12: double negative | C12: =3--2 | D12: 5 | E12: =IF(ISNUMBER(C12),IF(ABS(C12-D12)<0.000000001,"OK","FAIL"),"FAIL")
A13: OPE012 | B13: double unary coerces text to number | C13: =--"7" | D13: 7 | E13: =IF(ISNUMBER(C13),IF(ABS(C13-D13)<0.000000001,"OK","FAIL"),"FAIL")
A14: OPE013 | B14: text-number coercion in + | C14: ="5"+2 | D14: 7 | E14: =IF(ISNUMBER(C14),IF(ABS(C14-D14)<0.000000001,"OK","FAIL"),"FAIL")
A15: OPE014 | B15: boolean coerces to 1 | C15: =TRUE+1 | D15: 2 | E15: =IF(ISNUMBER(C15),IF(ABS(C15-D15)<0.000000001,"OK","FAIL"),"FAIL")
A16: OPE015 | C16: =TRUE*5 | D16: 5 | E16: =IF(ISNUMBER(C16),IF(ABS(C16-D16)<0.000000001,"OK","FAIL"),"FAIL")
A17: OPE016 | B17: comparisons coerce to 1 | C17: =(1=1)+(2=2) | D17: 2 | E17: =IF(ISNUMBER(C17),IF(ABS(C17-D17)<0.000000001,"OK","FAIL"),"FAIL")
A18: OPE017 | B18: unary minus after * | C18: =2*-3 | D18: -6 | E18: =IF(ISNUMBER(C18),IF(ABS(C18-D18)<0.000000001,"OK","FAIL"),"FAIL")
A19: OPE018 | B19: scientific literal | C19: =1E3+1 | D19: 1001 | E19: =IF(ISNUMBER(C19),IF(ABS(C19-D19)<0.000000001,"OK","FAIL"),"FAIL")
A20: OPE019 | B20: & concatenates numbers as text | C20: =7&8 | D20: 78 | E20: =IF(ISTEXT(C20),IF(EXACT(C20,D20),"OK","FAIL"),"FAIL")
A21: OPE020 | C21: ="a"&"b" | D21: ab | E21: =IF(ISTEXT(C21),IF(EXACT(C21,D21),"OK","FAIL"),"FAIL")
A22: OPE021 | C22: =1&"a" | D22: 1a | E22: =IF(ISTEXT(C22),IF(EXACT(C22,D22),"OK","FAIL"),"FAIL")
A23: OPE022 | B23: & never adds | C23: ="5"&2 | D23: 52 | E23: =IF(ISTEXT(C23),IF(EXACT(C23,D23),"OK","FAIL"),"FAIL")
A24: OPE023 | C24: =1=1 | D24: TRUE | E24: =IF(ISLOGICAL(C24),IF(C24=D24,"OK","FAIL"),"FAIL")
A25: OPE024 | C25: =1<>2 | D25: TRUE | E25: =IF(ISLOGICAL(C25),IF(C25=D25,"OK","FAIL"),"FAIL")
A26: OPE025 | B26: =is case-insensitive for text | C26: ="a"="A" | D26: TRUE | E26: =IF(ISLOGICAL(C26),IF(C26=D26,"OK","FAIL"),"FAIL")
A27: OPE026 | B27: text ordering | C27: ="a"<"b" | D27: TRUE | E27: =IF(ISLOGICAL(C27),IF(C27=D27,"OK","FAIL"),"FAIL")
A28: OPE027 | C28: =2>10 | D28: FALSE | E28: =IF(ISLOGICAL(C28),IF(C28=D28,"OK","FAIL"),"FAIL")
A29: OPE028 | B29: any text sorts above any number | C29: =99999<"a" | D29: TRUE | E29: =IF(ISLOGICAL(C29),IF(C29=D29,"OK","FAIL"),"FAIL")
A30: OPE029 | B30: logicals sort above numbers | C30: =TRUE>100 | D30: TRUE | E30: =IF(ISLOGICAL(C30),IF(C30=D30,"OK","FAIL"),"FAIL")
A31: OPE030 | C31: =1/0 | D31: #DIV/0! | E31: =IF(IFERROR(ERROR.TYPE(C31),0)=2,"OK","FAIL")
A32: OPE031 | C32: =0/0 | D32: #DIV/0! | E32: =IF(IFERROR(ERROR.TYPE(C32),0)=2,"OK","FAIL")
A33: OPE032 | B33: non-numeric text in arithmetic | C33: ="a"+1 | D33: #VALUE! | E33: =IF(IFERROR(ERROR.TYPE(C33),0)=3,"OK","FAIL")
A34: OPE033 | B34: errors propagate | C34: =1/0+1 | D34: #DIV/0! | E34: =IF(IFERROR(ERROR.TYPE(C34),0)=2,"OK","FAIL")

Sheet Math
A1: ID | B1: Note | C1: Actual | D1: Expected | E1: Check
A2: MAT001 | C2: =ABS(-5) | D2: 5 | E2: =IF(ISNUMBER(C2),IF(ABS(C2-D2)<0.000000001,"OK","FAIL"),"FAIL")
A3: MAT002 | B3: INT floors toward -inf | C3: =INT(-8.5) | D3: -9 | E3: =IF(ISNUMBER(C3),IF(ABS(C3-D3)<0.000000001,"OK","FAIL"),"FAIL")
A4: MAT003 | B4: TRUNC cuts toward zero (contrast INT) | C4: =TRUNC(-8.9) | D4: -8 | E4: =IF(ISNUMBER(C4),IF(ABS(C4-D4)<0.000000001,"OK","FAIL"),"FAIL")
A5: MAT004 | C5: =TRUNC(3.14159,2) | D5: 3.14 | E5: =IF(ISNUMBER(C5),IF(ABS(C5-D5)<0.000000001,"OK","FAIL"),"FAIL")
A6: MAT005 | B6: half away from zero | C6: =ROUND(2.5,0) | D6: 3 | E6: =IF(ISNUMBER(C6),IF(ABS(C6-D6)<0.000000001,"OK","FAIL"),"FAIL")
A7: MAT006 | B7: half away from zero (negative) | C7: =ROUND(-2.5,0) | D7: -3 | E7: =IF(ISNUMBER(C7),IF(ABS(C7-D7)<0.000000001,"OK","FAIL"),"FAIL")
A8: MAT007 | C8: =ROUND(2.4,0) | D8: 2 | E8: =IF(ISNUMBER(C8),IF(ABS(C8-D8)<0.000000001,"OK","FAIL"),"FAIL")
A9: MAT008 | C9: =ROUND(123.456,2) | D9: 123.46 | E9: =IF(ISNUMBER(C9),IF(ABS(C9-D9)<0.000000001,"OK","FAIL"),"FAIL")
A10: MAT009 | B10: negative digits round to tens | C10: =ROUND(15,-1) | D10: 20 | E10: =IF(ISNUMBER(C10),IF(ABS(C10-D10)<0.000000001,"OK","FAIL"),"FAIL")
A11: MAT010 | C11: =ROUNDUP(2.01,0) | D11: 3 | E11: =IF(ISNUMBER(C11),IF(ABS(C11-D11)<0.000000001,"OK","FAIL"),"FAIL")
A12: MAT011 | C12: =ROUNDDOWN(2.99,0) | D12: 2 | E12: =IF(ISNUMBER(C12),IF(ABS(C12-D12)<0.000000001,"OK","FAIL"),"FAIL")
A13: MAT012 | C13: =MOD(10,3) | D13: 1 | E13: =IF(ISNUMBER(C13),IF(ABS(C13-D13)<0.000000001,"OK","FAIL"),"FAIL")
A14: MAT013 | B14: result takes sign of divisor | C14: =MOD(-1,3) | D14: 2 | E14: =IF(ISNUMBER(C14),IF(ABS(C14-D14)<0.000000001,"OK","FAIL"),"FAIL")
A15: MAT014 | B15: result takes sign of divisor | C15: =MOD(1,-3) | D15: -2 | E15: =IF(ISNUMBER(C15),IF(ABS(C15-D15)<0.000000001,"OK","FAIL"),"FAIL")
A16: MAT015 | C16: =MOD(1,0) | D16: #DIV/0! | E16: =IF(IFERROR(ERROR.TYPE(C16),0)=2,"OK","FAIL")
A17: MAT016 | C17: =QUOTIENT(10,3) | D17: 3 | E17: =IF(ISNUMBER(C17),IF(ABS(C17-D17)<0.000000001,"OK","FAIL"),"FAIL")
A18: MAT017 | C18: =CEILING(2.1,1) | D18: 3 | E18: =IF(ISNUMBER(C18),IF(ABS(C18-D18)<0.000000001,"OK","FAIL"),"FAIL")
A19: MAT018 | B19: default rounds toward +inf | C19: =CEILING.MATH(-2.5) | D19: -2 | E19: =IF(ISNUMBER(C19),IF(ABS(C19-D19)<0.000000001,"OK","FAIL"),"FAIL")
A20: MAT019 | B20: rounds toward -inf | C20: =FLOOR.MATH(-2.5) | D20: -3 | E20: =IF(ISNUMBER(C20),IF(ABS(C20-D20)<0.000000001,"OK","FAIL"),"FAIL")
A21: MAT020 | C21: =MROUND(7,3) | D21: 6 | E21: =IF(ISNUMBER(C21),IF(ABS(C21-D21)<0.000000001,"OK","FAIL"),"FAIL")
A22: MAT021 | C22: =MROUND(8,3) | D22: 9 | E22: =IF(ISNUMBER(C22),IF(ABS(C22-D22)<0.000000001,"OK","FAIL"),"FAIL")
A23: MAT022 | C23: =EVEN(3) | D23: 4 | E23: =IF(ISNUMBER(C23),IF(ABS(C23-D23)<0.000000001,"OK","FAIL"),"FAIL")
A24: MAT023 | B24: away from zero | C24: =EVEN(-3) | D24: -4 | E24: =IF(ISNUMBER(C24),IF(ABS(C24-D24)<0.000000001,"OK","FAIL"),"FAIL")
A25: MAT024 | C25: =ODD(4) | D25: 5 | E25: =IF(ISNUMBER(C25),IF(ABS(C25-D25)<0.000000001,"OK","FAIL"),"FAIL")
A26: MAT025 | B26: away from zero | C26: =ODD(-4) | D26: -5 | E26: =IF(ISNUMBER(C26),IF(ABS(C26-D26)<0.000000001,"OK","FAIL"),"FAIL")
A27: MAT026 | C27: =SIGN(-3) | D27: -1 | E27: =IF(ISNUMBER(C27),IF(ABS(C27-D27)<0.000000001,"OK","FAIL"),"FAIL")
A28: MAT027 | C28: =SQRT(16) | D28: 4 | E28: =IF(ISNUMBER(C28),IF(ABS(C28-D28)<0.000000001,"OK","FAIL"),"FAIL")
A29: MAT028 | C29: =SQRT(-4) | D29: #NUM! | E29: =IF(IFERROR(ERROR.TYPE(C29),0)=6,"OK","FAIL")
A30: MAT029 | C30: =POWER(2,10) | D30: 1024 | E30: =IF(ISNUMBER(C30),IF(ABS(C30-D30)<0.000000001,"OK","FAIL"),"FAIL")
A31: MAT030 | C31: =EXP(0) | D31: 1 | E31: =IF(ISNUMBER(C31),IF(ABS(C31-D31)<0.000000001,"OK","FAIL"),"FAIL")
A32: MAT031 | C32: =LN(EXP(2)) | D32: 2 | E32: =IF(ISNUMBER(C32),IF(ABS(C32-D32)<0.000000001,"OK","FAIL"),"FAIL")
A33: MAT032 | C33: =LOG(8,2) | D33: 3 | E33: =IF(ISNUMBER(C33),IF(ABS(C33-D33)<0.000000001,"OK","FAIL"),"FAIL")
A34: MAT033 | C34: =LOG(-1) | D34: #NUM! | E34: =IF(IFERROR(ERROR.TYPE(C34),0)=6,"OK","FAIL")
A35: MAT034 | C35: =LOG10(1000) | D35: 3 | E35: =IF(ISNUMBER(C35),IF(ABS(C35-D35)<0.000000001,"OK","FAIL"),"FAIL")
A36: MAT035 | C36: =PI() | D36: 3.1415927 | E36: =IF(ISNUMBER(C36),IF(ABS(C36-D36)<0.000000001,"OK","FAIL"),"FAIL")
A37: MAT036 | C37: =SIN(0) | D37: 0 | E37: =IF(ISNUMBER(C37),IF(ABS(C37-D37)<0.000000001,"OK","FAIL"),"FAIL")
A38: MAT037 | C38: =COS(0) | D38: 1 | E38: =IF(ISNUMBER(C38),IF(ABS(C38-D38)<0.000000001,"OK","FAIL"),"FAIL")
A39: MAT038 | C39: =SIN(PI()/2) | D39: 1 | E39: =IF(ISNUMBER(C39),IF(ABS(C39-D39)<0.000000001,"OK","FAIL"),"FAIL")
A40: MAT039 | C40: =TAN(PI()/4) | D40: 1 | E40: =IF(ISNUMBER(C40),IF(ABS(C40-D40)<0.000000001,"OK","FAIL"),"FAIL")
...

Sheet Text
A1: ID | B1: Note | C1: Actual | D1: Expected | E1: Check
A2: TEX001 | C2: =LEN("hello") | D2: 5 | E2: =IF(ISNUMBER(C2),IF(ABS(C2-D2)<0.000000001,"OK","FAIL"),"FAIL")
A3: TEX002 | C3: =LEN("") | D3: 0 | E3: =IF(ISNUMBER(C3),IF(ABS(C3-D3)<0.000000001,"OK","FAIL"),"FAIL")
A4: TEX003 | C4: =LEFT("spreadsheet",6) | D4: spread | E4: =IF(ISTEXT(C4),IF(EXACT(C4,D4),"OK","FAIL"),"FAIL")
A5: TEX004 | C5: =RIGHT("spreadsheet",5) | D5: sheet | E5: =IF(ISTEXT(C5),IF(EXACT(C5,D5),"OK","FAIL"),"FAIL")
A6: TEX005 | C6: =MID("spreadsheet",7,5) | D6: sheet | E6: =IF(ISTEXT(C6),IF(EXACT(C6,D6),"OK","FAIL"),"FAIL")
A7: TEX006 | C7: =LOWER("MiXeD") | D7: mixed | E7: =IF(ISTEXT(C7),IF(EXACT(C7,D7),"OK","FAIL"),"FAIL")
A8: TEX007 | C8: =UPPER("mixed") | D8: MIXED | E8: =IF(ISTEXT(C8),IF(EXACT(C8,D8),"OK","FAIL"),"FAIL")
A9: TEX008 | B9: collapses inner runs too | C9: =TRIM(" a b ") | D9: a b | E9: =IF(ISTEXT(C9),IF(EXACT(C9,D9),"OK","FAIL"),"FAIL")
A10: TEX009 | B10: trims ' padded ' | C10: =LEN(TRIM(Data!H2)) | D10: 6 | E10: =IF(ISNUMBER(C10),IF(ABS(C10-D10)<0.000000001,"OK","FAIL"),"FAIL")
A11: TEX010 | C11: =REPT("ab",3) | D11: ababab | E11: =IF(ISTEXT(C11),IF(EXACT(C11,D11),"OK","FAIL"),"FAIL")
A12: TEX011 | B12: EXACT is case-sensitive | C12: =EXACT("a","A") | D12: FALSE | E12: =IF(ISLOGICAL(C12),IF(C12=D12,"OK","FAIL"),"FAIL")
A13: TEX012 | C13: =CONCAT("a","b","c") | D13: abc | E13: =IF(ISTEXT(C13),IF(EXACT(C13,D13),"OK","FAIL"),"FAIL")
A14: TEX013 | C14: =CONCATENATE("x",1) | D14: x1 | E14: =IF(ISTEXT(C14),IF(EXACT(C14,D14),"OK","FAIL"),"FAIL")
A15: TEX014 | C15: =FIND("b","abcabc") | D15: 2 | E15: =IF(ISNUMBER(C15),IF(ABS(C15-D15)<0.000000001,"OK","FAIL"),"FAIL")
A16: TEX015 | B16: start position | C16: =FIND("b","abcabc",3) | D16: 5 | E16: =IF(ISNUMBER(C16),IF(ABS(C16-D16)<0.000000001,"OK","FAIL"),"FAIL")
A17: TEX016 | B17: FIND is case-sensitive | C17: =FIND("B","abc") | D17: #VALUE! | E17: =IF(IFERROR(ERROR.TYPE(C17),0)=3,"OK","FAIL")
A18: TEX017 | B18: SEARCH is case-insensitive | C18: =SEARCH("B","abc") | D18: 2 | E18: =IF(ISNUMBER(C18),IF(ABS(C18-D18)<0.000000001,"OK","FAIL"),"FAIL")
A19: TEX018 | C19: =SUBSTITUTE("aaa","a","b") | D19: bbb | E19: =IF(ISTEXT(C19),IF(EXACT(C19,D19),"OK","FAIL"),"FAIL")
A20: TEX019 | B20: nth instance only | C20: =SUBSTITUTE("aaa","a","b",2) | D20: aba | E20: =IF(ISTEXT(C20),IF(EXACT(C20,D20),"OK","FAIL"),"FAIL")
A21: TEX020 | C21: =T("x") | D21: x | E21: =IF(ISTEXT(C21),IF(EXACT(C21,D21),"OK","FAIL"),"FAIL")
A22: TEX021 | C22: =VALUE("42") | D22: 42 | E22: =IF(ISNUMBER(C22),IF(ABS(C22-D22)<0.000000001,"OK","FAIL"),"FAIL")
A23: TEX022 | C23: =VALUE("3.14") | D23: 3.14 | E23: =IF(ISNUMBER(C23),IF(ABS(C23-D23)<0.000000001,"OK","FAIL"),"FAIL")
A24: TEX023 | C24: =TEXT(1234.5678,"0.00") | D24: 1234.57 | E24: =IF(ISTEXT(C24),IF(EXACT(C24,D24),"OK","FAIL"),"FAIL")
A25: TEX024 | C25: =TEXT(0.25,"0%") | D25: 25% | E25: =IF(ISTEXT(C25),IF(EXACT(C25,D25),"OK","FAIL"),"FAIL")
A26: TEX025 | C26: =TEXT(DATE(2026,8,3),"yyyy-mm-dd") | D26: 2026-08-03 | E26: =IF(ISTEXT(C26),IF(EXACT(C26,D26),"OK","FAIL"),"FAIL")
A27: TEX026 | C27: =CHAR(65) | D27: A | E27: =IF(ISTEXT(C27),IF(EXACT(C27,D27),"OK","FAIL"),"FAIL")
A28: TEX027 | C28: =UNICODE("A") | D28: 65 | E28: =IF(ISNUMBER(C28),IF(ABS(C28-D28)<0.000000001,"OK","FAIL"),"FAIL")
A29: TEX028 | C29: =TEXTJOIN("-",TRUE,"a","b","c") | D29: a-b-c | E29: =IF(ISTEXT(C29),IF(EXACT(C29,D29),"OK","FAIL"),"FAIL")
A30: TEX029 | B30: skip empties | C30: =TEXTJOIN(",",TRUE,"a","","b") | D30: a,b | E30: =IF(ISTEXT(C30),IF(EXACT(C30,D30),"OK","FAIL"),"FAIL")
A31: TEX030 | C31: =TEXTBEFORE("a-b-c","-") | D31: a | E31: =IF(ISTEXT(C31),IF(EXACT(C31,D31),"OK","FAIL"),"FAIL")
A32: TEX031 | C32: =TEXTBEFORE("a-b-c","-",2) | D32: a-b | E32: =IF(ISTEXT(C32),IF(EXACT(C32,D32),"OK","FAIL"),"FAIL")
A33: TEX032 | C33: =TEXTAFTER("a-b-c","-") | D33: b-c | E33: =IF(ISTEXT(C33),IF(EXACT(C33,D33),"OK","FAIL"),"FAIL")
A34: TEX033 | C34: =FORMULATEXT(Data!J1) | D34: ="="&"1+1" | E34: =IF(ISTEXT(C34),IF(EXACT(C34,D34),"OK","FAIL"),"FAIL")
A35: TEX034 | C35: =PROPER("hello world") | D35: Hello World | E35: =IF(ISTEXT(C35),IF(EXACT(C35,D35),"OK","FAIL"),"FAIL")
A36: TEX035 | B36: any non-letter is a word break | C36: =PROPER("2-cent's worth") | D36: 2-Cent'S Worth | E36: =IF(ISTEXT(C36),IF(EXACT(C36,D36),"OK","FAIL"),"FAIL")
A37: TEX036 | C37: =PROPER(Data!H3) | D37: Mixed Case | E37: =IF(ISTEXT(C37),IF(EXACT(C37,D37),"OK","FAIL"),"FAIL")
A38: TEX037 | C38: =CODE("A") | D38: 65 | E38: =IF(ISNUMBER(C38),IF(ABS(C38-D38)<0.000000001,"OK","FAIL"),"FAIL")
A39: TEX038 | B39: Win-1252 C1 range | C39: =CODE("€") | D39: 128 | E39: =IF(ISNUMBER(C39),IF(ABS(C39-D39)<0.000000001,"OK","FAIL"),"FAIL")
A40: TEX039 | B40: round-trip | C40: =CHAR(CODE("a")) | D40: a | E40: =IF(ISTEXT(C40),IF(EXACT(C40,D40),"OK","FAIL"),"FAIL")
...

Sheet Logical
A1: ID | B1: Note | C1: Actual | D1: Expected | E1: Check
A2: LOG001 | C2: =IF(1>2,"y","n") | D2: n | E2: =IF(ISTEXT(C2),IF(EXACT(C2,D2),"OK","FAIL"),"FAIL")
A3: LOG002 | B3: 0 is falsy | C3: =IF(0,"y","n") | D3: n | E3: =IF(ISTEXT(C3),IF(EXACT(C3,D3),"OK","FAIL"),"FAIL")
A4: LOG003 | B4: nonzero is truthy | C4: =IF(3,"y","n") | D4: y | E4: =IF(ISTEXT(C4),IF(EXACT(C4,D4),"OK","FAIL"),"FAIL")
A5: LOG004 | C5: =AND(TRUE,1=1) | D5: TRUE | E5: =IF(ISLOGICAL(C5),IF(C5=D5,"OK","FAIL"),"FAIL")
A6: LOG005 | C6: =AND(TRUE,FALSE) | D6: FALSE | E6: =IF(ISLOGICAL(C6),IF(C6=D6,"OK","FAIL"),"FAIL")
A7: LOG006 | C7: =OR(FALSE,FALSE) | D7: FALSE | E7: =IF(ISLOGICAL(C7),IF(C7=D7,"OK","FAIL"),"FAIL")
A8: LOG007 | B8: numeric coercion | C8: =OR(0,1) | D8: TRUE | E8: =IF(ISLOGICAL(C8),IF(C8=D8,"OK","FAIL"),"FAIL")
A9: LOG008 | C9: =XOR(TRUE,TRUE) | D9: FALSE | E9: =IF(ISLOGICAL(C9),IF(C9=D9,"OK","FAIL"),"FAIL")
A10: LOG009 | B10: even count of TRUE | C10: =XOR(TRUE,FALSE,TRUE) | D10: FALSE | E10: =IF(ISLOGICAL(C10),IF(C10=D10,"OK","FAIL"),"FAIL")
A11: LOG010 | C11: =NOT(FALSE) | D11: TRUE | E11: =IF(ISLOGICAL(C11),IF(C11=D11,"OK","FAIL"),"FAIL")
A12: LOG011 | C12: =IFERROR(1/0,"caught") | D12: caught | E12: =IF(ISTEXT(C12),IF(EXACT(C12,D12),"OK","FAIL"),"FAIL")
A13: LOG012 | B13: no error passes through | C13: =IFERROR(42,"x") | D13: 42 | E13: =IF(ISNUMBER(C13),IF(ABS(C13-D13)<0.000000001,"OK","FAIL"),"FAIL")
A14: LOG013 | C14: =IFNA(NA(),"na") | D14: na | E14: =IF(ISTEXT(C14),IF(EXACT(C14,D14),"OK","FAIL"),"FAIL")
A15: LOG014 | B15: IFNA only catches #N/A | C15: =IFNA(1/0,"na") | D15: #DIV/0! | E15: =IF(IFERROR(ERROR.TYPE(C15),0)=2,"OK","FAIL")
A16: LOG015 | C16: =IFS(FALSE,"a",TRUE,"b") | D16: b | E16: =IF(ISTEXT(C16),IF(EXACT(C16,D16),"OK","FAIL"),"FAIL")
A17: LOG016 | B17: no branch matched | C17: =IFS(FALSE,"a") | D17: #N/A | E17: =IF(IFERROR(ERROR.TYPE(C17),0)=7,"OK","FAIL")
A18: LOG017 | C18: =SWITCH(2,1,"one",2,"two","def") | D18: two | E18: =IF(ISTEXT(C18),IF(EXACT(C18,D18),"OK","FAIL"),"FAIL")
A19: LOG018 | B19: default arm | C19: =SWITCH(9,1,"one","def") | D19: def | E19: =IF(ISTEXT(C19),IF(EXACT(C19,D19),"OK","FAIL"),"FAIL")
A20: LOG019 | C20: =TRUE() | D20: TRUE | E20: =IF(ISLOGICAL(C20),IF(C20=D20,"OK","FAIL"),"FAIL")

Sheet Lookup
A1: ID | B1: Note | C1: Actual | D1: Expected | E1: Check
A2: LOO001 | C2: =VLOOKUP("Cherry",Data!A2:C6,3,FALSE) | D2: 3.2 | E2: =IF(ISNUMBER(C2),IF(ABS(C2-D2)<0.000000001,"OK","FAIL"),"FAIL")
A3: LOO002 | B3: case-insensitive | C3: =VLOOKUP("cherry",Data!A2:C6,3,FALSE) | D3: 3.2 | E3: =IF(ISNUMBER(C3),IF(ABS(C3-D3)<0.000000001,"OK","FAIL"),"FAIL")
A4: LOO003 | C4: =VLOOKUP("Zzz",Data!A2:C6,2,FALSE) | D4: #N/A | E4: =IF(IFERROR(ERROR.TYPE(C4),0)=7,"OK","FAIL")
A5: LOO004 | B5: approx falls back to Cherry | C5: =VLOOKUP("Coconut",Data!A2:C6,2,TRUE) | D5: 5 | E5: =IF(ISNUMBER(C5),IF(ABS(C5-D5)<0.000000001,"OK","FAIL"),"FAIL")
A6: LOO005 | C6: =HLOOKUP("b",Data!K1:M2,2,FALSE) | D6: 2 | E6: =IF(ISNUMBER(C6),IF(ABS(C6-D6)<0.000000001,"OK","FAIL"),"FAIL")
A7: LOO006 | C7: =INDEX(Data!A2:C6,2,1) | D7: Banana | E7: =IF(ISTEXT(C7),IF(EXACT(C7,D7),"OK","FAIL"),"FAIL")
A8: LOO007 | B8: vector form | C8: =INDEX(Data!E1:E8,4) | D8: 1 | E8: =IF(ISNUMBER(C8),IF(ABS(C8-D8)<0.000000001,"OK","FAIL"),"FAIL")
A9: LOO008 | C9: =MATCH(8,Data!E1:E8,0) | D9: 3 | E9: =IF(ISNUMBER(C9),IF(ABS(C9-D9)<0.000000001,"OK","FAIL"),"FAIL")
A10: LOO009 | C10: =MATCH("Date",Data!A2:A6,0) | D10: 4 | E10: =IF(ISNUMBER(C10),IF(ABS(C10-D10)<0.000000001,"OK","FAIL"),"FAIL")
A11: LOO010 | B11: approx over sorted 10..50 | C11: =MATCH(35,Data!F3:F7,1) | D11: 3 | E11: =IF(ISNUMBER(C11),IF(ABS(C11-D11)<0.000000001,"OK","FAIL"),"FAIL")
A12: LOO011 | B12: INDEX+MATCH | C12: =INDEX(Data!C2:C6,MATCH("Banana",Data!A2:A6,0)) | D12: 0.25 | E12: =IF(ISNUMBER(C12),IF(ABS(C12-D12)<0.000000001,"OK","FAIL"),"FAIL")
A13: LOO012 | C13: =CHOOSE(3,"a","b","c") | D13: c | E13: =IF(ISTEXT(C13),IF(EXACT(C13,D13),"OK","FAIL"),"FAIL")
A14: LOO013 | B14: lands on B3 | C14: =OFFSET(Data!A2,1,1) | D14: 20 | E14: =IF(ISNUMBER(C14),IF(ABS(C14-D14)<0.000000001,"OK","FAIL"),"FAIL")
A15: LOO014 | B15: resized range 5+3+8+1 | C15: =SUM(OFFSET(Data!E1,0,0,4,1)) | D15: 17 | E15: =IF(ISNUMBER(C15),IF(ABS(C15-D15)<0.000000001,"OK","FAIL"),"FAIL")
A16: LOO015 | C16: =ROWS(Data!A2:C6) | D16: 5 | E16: =IF(ISNUMBER(C16),IF(ABS(C16-D16)<0.000000001,"OK","FAIL"),"FAIL")
A17: LOO016 | C17: =COLUMNS(Data!A2:C6) | D17: 3 | E17: =IF(ISNUMBER(C17),IF(ABS(C17-D17)<0.000000001,"OK","FAIL"),"FAIL")
A18: LOO017 | C18: =INDIRECT("Data!B3") | D18: 20 | E18: =IF(ISNUMBER(C18),IF(ABS(C18-D18)<0.000000001,"OK","FAIL"),"FAIL")
A19: LOO018 | B19: R1C1 mode | C19: =INDIRECT("Data!R3C2",FALSE) | D19: 20 | E19: =IF(ISNUMBER(C19),IF(ABS(C19-D19)<0.000000001,"OK","FAIL"),"FAIL")
A20: LOO019 | B20: R1C1 range | C20: =SUM(INDIRECT("Data!R1C5:R4C5",FALSE)) | D20: 17 | E20: =IF(ISNUMBER(C20),IF(ABS(C20-D20)<0.000000001,"OK","FAIL"),"FAIL")
A21: LOO020 | B21: defined name through INDIRECT | C21: =INDIRECT("TaxRate") | D21: 0.15 | E21: =IF(ISNUMBER(C21),IF(ABS(C21-D21)<0.000000001,"OK","FAIL"),"FAIL")
A22: LOO021 | B22: defined-name table | C22: =VLOOKUP("Date",PriceTable,2,FALSE) | D22: 15 | E22: =IF(ISNUMBER(C22),IF(ABS(C22-D22)<0.000000001,"OK","FAIL"),"FAIL")
A23: LOO022 | B23: defined name in arithmetic | C23: =TaxRate*100 | D23: 15 | E23: =IF(ISNUMBER(C23),IF(ABS(C23-D23)<0.000000001,"OK","FAIL"),"FAIL")
A24: LOO023 | C24: =XLOOKUP("Date",Data!A2:A6,Data!B2:B6) | D24: 15 | E24: =IF(ISNUMBER(C24),IF(ABS(C24-D24)<0.000000001,"OK","FAIL"),"FAIL")
A25: LOO024 | C25: =XLOOKUP("Zzz",Data!A2:A6,Data!B2:B6,"missing") | D25: missing | E25: =IF(ISTEXT(C25),IF(EXACT(C25,D25),"OK","FAIL"),"FAIL")
A26: LOO025 | B26: vector LOOKUP approx | C26: =LOOKUP(35,Data!F3:F7) | D26: 30 | E26: =IF(ISNUMBER(C26),IF(ABS(C26-D26)<0.000000001,"OK","FAIL"),"FAIL")
A27: LOO026 | C27: =ERROR.TYPE(1/0) | D27: 2 | E27: =IF(ISNUMBER(C27),IF(ABS(C27-D27)<0.000000001,"OK","FAIL"),"FAIL")
A28: LOO027 | C28: =TYPE(1) | D28: 1 | E28: =IF(ISNUMBER(C28),IF(ABS(C28-D28)<0.000000001,"OK","FAIL"),"FAIL")
A29: LOO028 | C29: =TYPE("a") | D29: 2 | E29: =IF(ISNUMBER(C29),IF(ABS(C29-D29)<0.000000001,"OK","FAIL"),"FAIL")
A30: LOO029 | C30: =TYPE(TRUE) | D30: 4 | E30: =IF(ISNUMBER(C30),IF(ABS(C30-D30)<0.000000001,"OK","FAIL"),"FAIL")
A31: LOO030 | C31: =N(TRUE) | D31: 1 | E31: =IF(ISNUMBER(C31),IF(ABS(C31-D31)<0.000000001,"OK","FAIL"),"FAIL")
A32: LOO031 | C32: =N("a") | D32: 0 | E32: =IF(ISNUMBER(C32),IF(ABS(C32-D32)<0.000000001,"OK","FAIL"),"FAIL")
A33: LOO032 | C33: =ADDRESS(1,1) | D33: $A$1 | E33: =IF(ISTEXT(C33),IF(EXACT(C33,D33),"OK","FAIL"),"FAIL")
A34: LOO033 | B34: row absolute | C34: =ADDRESS(2,3,2) | D34: C$2 | E34: =IF(ISTEXT(C34),IF(EXACT(C34,D34),"OK","FAIL"),"FAIL")
A35: LOO034 | B35: column absolute | C35: =ADDRESS(2,3,3) | D35: $C2 | E35: =IF(ISTEXT(C35),IF(EXACT(C35,D35),"OK","FAIL"),"FAIL")
A36: LOO035 | B36: relative | C36: =ADDRESS(2,3,4) | D36: C2 | E36: =IF(ISTEXT(C36),IF(EXACT(C36,D36),"OK","FAIL"),"FAIL")
A37: LOO036 | B37: R1C1 absolute | C37: =ADDRESS(2,3,1,FALSE) | D37: R2C3 | E37: =IF(ISTEXT(C37),IF(EXACT(C37,D37),"OK","FAIL"),"FAIL")
A38: LOO037 | B38: R1C1 relative | C38: =ADDRESS(2,3,4,FALSE) | D38: R[2]C[3] | E38: =IF(ISTEXT(C38),IF(EXACT(C38,D38),"OK","FAIL"),"FAIL")
A39: LOO038 | B39: sheet prefix | C39: =ADDRESS(1,1,1,TRUE,"Data") | D39: Data!$A$1 | E39: =IF(ISTEXT(C39),IF(EXACT(C39,D39),"OK","FAIL"),"FAIL")
A40: LOO039 | B40: quoted sheet | C40: =ADDRESS(1,1,1,TRUE,"My Sheet") | D40: 'My Sheet'!$A$1 | E40: =IF(ISTEXT(C40),IF(EXACT(C40,D40),"OK","FAIL"),"FAIL")
...

Sheet Dates
A1: ID | B1: Note | C1: Actual | D1: Expected | E1: Check
A2: DAT001 | C2: =DATE(2026,8,3) | D2: 46237 | E2: =IF(ISNUMBER(C2),IF(ABS(C2-D2)<0.000000001,"OK","FAIL"),"FAIL")
A3: DAT002 | C3: =YEAR(DATE(2026,8,3)) | D3: 2026 | E3: =IF(ISNUMBER(C3),IF(ABS(C3-D3)<0.000000001,"OK","FAIL"),"FAIL")
A4: DAT003 | C4: =MONTH(DATE(2026,8,3)) | D4: 8 | E4: =IF(ISNUMBER(C4),IF(ABS(C4-D4)<0.000000001,"OK","FAIL"),"FAIL")
A5: DAT004 | C5: =DAY(DATE(2026,8,3)) | D5: 3 | E5: =IF(ISNUMBER(C5),IF(ABS(C5-D5)<0.000000001,"OK","FAIL"),"FAIL")
A6: DAT005 | B6: month overflow rolls | C6: =DATE(2026,13,1) | D6: 46388 | E6: =IF(ISNUMBER(C6),IF(ABS(C6-D6)<0.000000001,"OK","FAIL"),"FAIL")
A7: DAT006 | B7: day overflow rolls | C7: =DATE(2026,2,30) | D7: 46083 | E7: =IF(ISNUMBER(C7),IF(ABS(C7-D7)<0.000000001,"OK","FAIL"),"FAIL")
A8: DAT007 | B8: 2026-08-03 is a Monday | C8: =WEEKDAY(DATE(2026,8,3)) | D8: 2 | E8: =IF(ISNUMBER(C8),IF(ABS(C8-D8)<0.000000001,"OK","FAIL"),"FAIL")
A9: DAT008 | B9: type 2: Monday=1 | C9: =WEEKDAY(DATE(2026,8,3),2) | D9: 1 | E9: =IF(ISNUMBER(C9),IF(ABS(C9-D9)<0.000000001,"OK","FAIL"),"FAIL")
A10: DAT009 | B10: clamps to month end | C10: =EDATE(DATE(2026,1,31),1) | D10: 46081 | E10: =IF(ISNUMBER(C10),IF(ABS(C10-D10)<0.000000001,"OK","FAIL"),"FAIL")
A11: DAT010 | C11: =EOMONTH(DATE(2026,2,10),0) | D11: 46081 | E11: =IF(ISNUMBER(C11),IF(ABS(C11-D11)<0.000000001,"OK","FAIL"),"FAIL")
A12: DAT011 | B12: leap year | C12: =EOMONTH(DATE(2024,2,10),0) | D12: 45351 | E12: =IF(ISNUMBER(C12),IF(ABS(C12-D12)<0.000000001,"OK","FAIL"),"FAIL")
A13: DAT012 | C13: =DAYS(DATE(2026,12,31),DATE(2026,1,1)) | D13: 364 | E13: =IF(ISNUMBER(C13),IF(ABS(C13-D13)<0.000000001,"OK","FAIL"),"FAIL")
A14: DAT013 | B14: US method | C14: =DAYS360(DATE(2026,1,1),DATE(2026,12,31)) | D14: 360 | E14: =IF(ISNUMBER(C14),IF(ABS(C14-D14)<0.000000001,"OK","FAIL"),"FAIL")
A15: DAT014 | C15: =DATEDIF(DATE(2020,1,15),DATE(2026,8,3),"Y") | D15: 6 | E15: =IF(ISNUMBER(C15),IF(ABS(C15-D15)<0.000000001,"OK","FAIL"),"FAIL")
A16: DAT015 | C16: =DATEDIF(DATE(2020,1,15),DATE(2026,8,3),"M") | D16: 78 | E16: =IF(ISNUMBER(C16),IF(ABS(C16-D16)<0.000000001,"OK","FAIL"),"FAIL")
A17: DAT016 | C17: =TIME(12,30,0) | D17: 0.52083333 | E17: =IF(ISNUMBER(C17),IF(ABS(C17-D17)<0.000000001,"OK","FAIL"),"FAIL")
A18: DAT017 | C18: =HOUR(0.75) | D18: 18 | E18: =IF(ISNUMBER(C18),IF(ABS(C18-D18)<0.000000001,"OK","FAIL"),"FAIL")
A19: DAT018 | C19: =MINUTE(TIME(1,23,45)) | D19: 23 | E19: =IF(ISNUMBER(C19),IF(ABS(C19-D19)<0.000000001,"OK","FAIL"),"FAIL")
A20: DAT019 | C20: =SECOND(TIME(1,2,3)) | D20: 3 | E20: =IF(ISNUMBER(C20),IF(ABS(C20-D20)<0.000000001,"OK","FAIL"),"FAIL")
A21: DAT020 | B21: ISO parse | C21: =DATEVALUE("2026-08-03") | D21: 46237 | E21: =IF(ISNUMBER(C21),IF(ABS(C21-D21)<0.000000001,"OK","FAIL"),"FAIL")
A22: DAT021 | C22: =TIMEVALUE("12:00") | D22: 0.5 | E22: =IF(ISNUMBER(C22),IF(ABS(C22-D22)<0.000000001,"OK","FAIL"),"FAIL")
A23: DAT022 | C23: =WEEKNUM(DATE(2026,1,1)) | D23: 1 | E23: =IF(ISNUMBER(C23),IF(ABS(C23-D23)<0.000000001,"OK","FAIL"),"FAIL")
A24: DAT023 | B24: Jan 1 2026 is a Thursday | C24: =ISOWEEKNUM(DATE(2026,1,1)) | D24: 1 | E24: =IF(ISNUMBER(C24),IF(ABS(C24-D24)<0.000000001,"OK","FAIL"),"FAIL")
A25: DAT024 | B25: Mon..Fri | C25: =NETWORKDAYS(DATE(2026,8,3),DATE(2026,8,7)) | D25: 5 | E25: =IF(ISNUMBER(C25),IF(ABS(C25-D25)<0.000000001,"OK","FAIL"),"FAIL")
A26: DAT025 | B26: Fri+1 skips weekend | C26: =WORKDAY(DATE(2026,8,7),1) | D26: 46244 | E26: =IF(ISNUMBER(C26),IF(ABS(C26-D26)<0.000000001,"OK","FAIL"),"FAIL")
A27: DAT026 | B27: basis 0 | C27: =YEARFRAC(DATE(2026,1,1),DATE(2027,1,1)) | D27: 1 | E27: =IF(ISNUMBER(C27),IF(ABS(C27-D27)<0.000000001,"OK","FAIL"),"FAIL")
A28: DAT027 | B28: shape check only | C28: =YEAR(TODAY())>=2026 | D28: TRUE | E28: =IF(ISLOGICAL(C28),IF(C28=D28,"OK","FAIL"),"FAIL")
A29: DAT028 | B29: shape check only | C29: =NOW()>=TODAY() | D29: TRUE | E29: =IF(ISLOGICAL(C29),IF(C29=D29,"OK","FAIL"),"FAIL")

Sheet Stats
A1: ID | B1: Note | C1: Actual | D1: Expected | E1: Check
A2: STA001 | C2: =AVERAGE(Data!E1:E8) | D2: 4.875 | E2: =IF(ISNUMBER(C2),IF(ABS(C2-D2)<0.000000001,"OK","FAIL"),"FAIL")
A3: STA002 | C3: =AVERAGE(1,2,3) | D3: 2 | E3: =IF(ISNUMBER(C3),IF(ABS(C3-D3)<0.000000001,"OK","FAIL"),"FAIL")
A4: STA003 | B4: TRUE counts as 1 | C4: =AVERAGEA(1,TRUE) | D4: 1 | E4: =IF(ISNUMBER(C4),IF(ABS(C4-D4)<0.000000001,"OK","FAIL"),"FAIL")
A5: STA004 | C5: =MEDIAN(Data!E1:E8) | D5: 4.5 | E5: =IF(ISNUMBER(C5),IF(ABS(C5-D5)<0.000000001,"OK","FAIL"),"FAIL")
A6: STA005 | C6: =MAX(Data!E1:E8) | D6: 9 | E6: =IF(ISNUMBER(C6),IF(ABS(C6-D6)<0.000000001,"OK","FAIL"),"FAIL")
A7: STA006 | C7: =MIN(Data!E1:E8) | D7: 1 | E7: =IF(ISNUMBER(C7),IF(ABS(C7-D7)<0.000000001,"OK","FAIL"),"FAIL")
A8: STA007 | C8: =LARGE(Data!E1:E8,2) | D8: 8 | E8: =IF(ISNUMBER(C8),IF(ABS(C8-D8)<0.000000001,"OK","FAIL"),"FAIL")
A9: STA008 | C9: =SMALL(Data!E1:E8,3) | D9: 3 | E9: =IF(ISNUMBER(C9),IF(ABS(C9-D9)<0.000000001,"OK","FAIL"),"FAIL")
A10: STA009 | B10: only the number; TRUE/text/error don't count | C10: =COUNT(Data!G1:G5) | D10: 1 | E10: =IF(ISNUMBER(C10),IF(ABS(C10-D10)<0.000000001,"OK","FAIL"),"FAIL")
A11: STA010 | B11: everything but the blank | C11: =COUNTA(Data!G1:G5) | D11: 4 | E11: =IF(ISNUMBER(C11),IF(ABS(C11-D11)<0.000000001,"OK","FAIL"),"FAIL")
A12: STA011 | C12: =COUNTBLANK(Data!G1:G5) | D12: 1 | E12: =IF(ISNUMBER(C12),IF(ABS(C12-D12)<0.000000001,"OK","FAIL"),"FAIL")
A13: STA012 | C13: =COUNTIF(Data!E1:E8,">4") | D13: 4 | E13: =IF(ISNUMBER(C13),IF(ABS(C13-D13)<0.000000001,"OK","FAIL"),"FAIL")
A14: STA013 | B14: wildcard contains | C14: =COUNTIF(Data!A2:A6,"*e*") | D14: 4 | E14: =IF(ISNUMBER(C14),IF(ABS(C14-D14)<0.000000001,"OK","FAIL"),"FAIL")
A15: STA014 | C15: =COUNTIFS(Data!E1:E8,">2",Data!E1:E8,"<8") | D15: 4 | E15: =IF(ISNUMBER(C15),IF(ABS(C15-D15)<0.000000001,"OK","FAIL"),"FAIL")
A16: STA015 | C16: =AVERAGEIF(Data!E1:E8,">4") | D16: 7.25 | E16: =IF(ISNUMBER(C16),IF(ABS(C16-D16)<0.000000001,"OK","FAIL"),"FAIL")
A17: STA016 | B17: exact | C17: =STDEV.P(2,4,4,4,5,5,7,9) | D17: 2 | E17: =IF(ISNUMBER(C17),IF(ABS(C17-D17)<0.000000001,"OK","FAIL"),"FAIL")
A18: STA017 | B18: exact | C18: =VAR.P(2,4,4,4,5,5,7,9) | D18: 4 | E18: =IF(ISNUMBER(C18),IF(ABS(C18-D18)<0.000000001,"OK","FAIL"),"FAIL")
A19: STA018 | B19: descending default | C19: =RANK.EQ(7,Data!E1:E8) | D19: 3 | E19: =IF(ISNUMBER(C19),IF(ABS(C19-D19)<0.000000001,"OK","FAIL"),"FAIL")
A20: STA019 | C20: =GEOMEAN(2,8) | D20: 4 | E20: =IF(ISNUMBER(C20),IF(ABS(C20-D20)<0.000000001,"OK","FAIL"),"FAIL")
A21: STA020 | C21: =HARMEAN(2,6) | D21: 3 | E21: =IF(ISNUMBER(C21),IF(ABS(C21-D21)<0.000000001,"OK","FAIL"),"FAIL")
A22: STA021 | C22: =DEVSQ(1,2,3) | D22: 2 | E22: =IF(ISNUMBER(C22),IF(ABS(C22-D22)<0.000000001,"OK","FAIL"),"FAIL")
A23: STA022 | C23: =MAXIFS(Data!B2:B6,Data!A2:A6,"<>Banana") | D23: 15 | E23: =IF(ISNUMBER(C23),IF(ABS(C23-D23)<0.000000001,"OK","FAIL"),"FAIL")
A24: STA023 | C24: =MINIFS(Data!B2:B6,Data!A2:A6,"<>Banana") | D24: 5 | E24: =IF(ISNUMBER(C24),IF(ABS(C24-D24)<0.000000001,"OK","FAIL"),"FAIL")
A25: STA024 | C25: =MODE(1,2,2,3) | D25: 2 | E25: =IF(ISNUMBER(C25),IF(ABS(C25-D25)<0.000000001,"OK","FAIL"),"FAIL")
A26: STA025 | B26: tie goes to first seen | C26: =MODE(3,3,2,2) | D26: 3 | E26: =IF(ISNUMBER(C26),IF(ABS(C26-D26)<0.000000001,"OK","FAIL"),"FAIL")
A27: STA026 | B27: no repeats | C27: =MODE(1,2,3) | D27: #N/A | E27: =IF(IFERROR(ERROR.TYPE(C27),0)=7,"OK","FAIL")
A28: STA027 | B28: all distinct | C28: =MODE(Data!E1:E8) | D28: #N/A | E28: =IF(IFERROR(ERROR.TYPE(C28),0)=7,"OK","FAIL")

Sheet Info
A1: ID | B1: Note | C1: Actual | D1: Expected | E1: Check
A2: INF001 | C2: =ISBLANK(Data!G4) | D2: TRUE | E2: =IF(ISLOGICAL(C2),IF(C2=D2,"OK","FAIL"),"FAIL")
A3: INF002 | B3: empty text is not blank | C3: =ISBLANK("") | D3: FALSE | E3: =IF(ISLOGICAL(C3),IF(C3=D3,"OK","FAIL"),"FAIL")
A4: INF003 | C4: =ISNUMBER(1) | D4: TRUE | E4: =IF(ISLOGICAL(C4),IF(C4=D4,"OK","FAIL"),"FAIL")
A5: INF004 | B5: no coercion in IS* | C5: =ISNUMBER("1") | D5: FALSE | E5: =IF(ISLOGICAL(C5),IF(C5=D5,"OK","FAIL"),"FAIL")
A6: INF005 | C6: =ISTEXT("a") | D6: TRUE | E6: =IF(ISLOGICAL(C6),IF(C6=D6,"OK","FAIL"),"FAIL")
A7: INF006 | C7: =ISTEXT(1) | D7: FALSE | E7: =IF(ISLOGICAL(C7),IF(C7=D7,"OK","FAIL"),"FAIL")
A8: INF007 | C8: =ISLOGICAL(TRUE) | D8: TRUE | E8: =IF(ISLOGICAL(C8),IF(C8=D8,"OK","FAIL"),"FAIL")
A9: INF008 | C9: =ISLOGICAL(1) | D9: FALSE | E9: =IF(ISLOGICAL(C9),IF(C9=D9,"OK","FAIL"),"FAIL")
A10: INF009 | C10: =ISNA(NA()) | D10: TRUE | E10: =IF(ISLOGICAL(C10),IF(C10=D10,"OK","FAIL"),"FAIL")
A11: INF010 | C11: =ISNA(1/0) | D11: FALSE | E11: =IF(ISLOGICAL(C11),IF(C11=D11,"OK","FAIL"),"FAIL")
A12: INF011 | B12: ISERR = all errors except #N/A | C12: =ISERR(1/0) | D12: TRUE | E12: =IF(ISLOGICAL(C12),IF(C12=D12,"OK","FAIL"),"FAIL")
A13: INF012 | C13: =ISERR(NA()) | D13: FALSE | E13: =IF(ISLOGICAL(C13),IF(C13=D13,"OK","FAIL"),"FAIL")
A14: INF013 | C14: =ISERROR(NA()) | D14: TRUE | E14: =IF(ISLOGICAL(C14),IF(C14=D14,"OK","FAIL"),"FAIL")
A15: INF014 | C15: =ISEVEN(4) | D15: TRUE | E15: =IF(ISLOGICAL(C15),IF(C15=D15,"OK","FAIL"),"FAIL")
A16: INF015 | B16: truncates first | C16: =ISEVEN(2.5) | D16: TRUE | E16: =IF(ISLOGICAL(C16),IF(C16=D16,"OK","FAIL"),"FAIL")
A17: INF016 | C17: =ISODD(4) | D17: FALSE | E17: =IF(ISLOGICAL(C17),IF(C17=D17,"OK","FAIL"),"FAIL")
A18: INF017 | C18: =ISNONTEXT(1) | D18: TRUE | E18: =IF(ISLOGICAL(C18),IF(C18=D18,"OK","FAIL"),"FAIL")
A19: INF018 | C19: =ISFORMULA(Data!J1) | D19: TRUE | E19: =IF(ISLOGICAL(C19),IF(C19=D19,"OK","FAIL"),"FAIL")
A20: INF019 | C20: =ISREF(Data!A1) | D20: TRUE | E20: =IF(ISLOGICAL(C20),IF(C20=D20,"OK","FAIL"),"FAIL")

Sheet Financial
A1: ID | B1: Note | C1: Actual | D1: Expected | E1: Check
A2: FIN001 | B2: vs closed form | C2: =PMT(0.05/12,360,200000) | D2: =-200000*(0.05/12)/(1-(1+0.05/12)^-360) | E2: =IF(ISNUMBER(C2),IF(ABS(C2-D2)<0.000000001,"OK","FAIL"),"FAIL")
A3: FIN002 | C3: =FV(0.1,2,0,-100) | D3: 121 | E3: =IF(ISNUMBER(C3),IF(ABS(C3-D3)<0.000000001,"OK","FAIL"),"FAIL")
A4: FIN003 | C4: =PV(0.1,1,0,-110) | D4: 100 | E4: =IF(ISNUMBER(C4),IF(ABS(C4-D4)<0.000000001,"OK","FAIL"),"FAIL")
A5: FIN004 | C5: =NPER(0.1,0,-100,121) | D5: 2 | E5: =IF(ISNUMBER(C5),IF(ABS(C5-D5)<0.000000001,"OK","FAIL"),"FAIL")
A6: FIN005 | C6: =RATE(2,0,-100,121) | D6: 0.1 | E6: =IF(ISNUMBER(C6),IF(ABS(C6-D6)<0.000000001,"OK","FAIL"),"FAIL")
A7: FIN006 | B7: vs closed form | C7: =NPV(0.1,100,200) | D7: =100/1.1+200/1.1^2 | E7: =IF(ISNUMBER(C7),IF(ABS(C7-D7)<0.000000001,"OK","FAIL"),"FAIL")
A8: FIN007 | B8: -100 then 110 | C8: =IRR(Data!O1:O2) | D8: 0.1 | E8: =IF(ISNUMBER(C8),IF(ABS(C8-D8)<0.000000001,"OK","FAIL"),"FAIL")
A9: FIN008 | C9: =SLN(10000,1000,5) | D9: 1800 | E9: =IF(ISNUMBER(C9),IF(ABS(C9-D9)<0.000000001,"OK","FAIL"),"FAIL")
A10: FIN009 | C10: =DDB(10000,1000,5,1) | D10: 4000 | E10: =IF(ISNUMBER(C10),IF(ABS(C10-D10)<0.000000001,"OK","FAIL"),"FAIL")
A11: FIN010 | C11: =SYD(10000,1000,5,1) | D11: 3000 | E11: =IF(ISNUMBER(C11),IF(ABS(C11-D11)<0.000000001,"OK","FAIL"),"FAIL")
A12: FIN011 | B12: vs closed form | C12: =EFFECT(0.12,12) | D12: =1.01^12-1 | E12: =IF(ISNUMBER(C12),IF(ABS(C12-D12)<0.000000001,"OK","FAIL"),"FAIL")
A13: FIN012 | C13: =NOMINAL(0.126825030131969,12) | D13: 0.12 | E13: =IF(ISNUMBER(C13),IF(ABS(C13-D13)<0.000000001,"OK","FAIL"),"FAIL")

Sheet Engineering
A1: ID | B1: Note | C1: Actual | D1: Expected | E1: Check
A2: ENG001 | C2: =BIN2DEC(1010) | D2: 10 | E2: =IF(ISNUMBER(C2),IF(ABS(C2-D2)<0.000000001,"OK","FAIL"),"FAIL")
A3: ENG002 | C3: =DEC2BIN(10) | D3: 1010 | E3: =IF(ISTEXT(C3),IF(EXACT(C3,D3),"OK","FAIL"),"FAIL")
A4: ENG003 | C4: =HEX2DEC("FF") | D4: 255 | E4: =IF(ISNUMBER(C4),IF(ABS(C4-D4)<0.000000001,"OK","FAIL"),"FAIL")
A5: ENG004 | C5: =DEC2HEX(255) | D5: FF | E5: =IF(ISTEXT(C5),IF(EXACT(C5,D5),"OK","FAIL"),"FAIL")
A6: ENG005 | C6: =OCT2DEC(17) | D6: 15 | E6: =IF(ISNUMBER(C6),IF(ABS(C6-D6)<0.000000001,"OK","FAIL"),"FAIL")
A7: ENG006 | C7: =DEC2OCT(15) | D7: 17 | E7: =IF(ISTEXT(C7),IF(EXACT(C7,D7),"OK","FAIL"),"FAIL")
A8: ENG007 | C8: =BITAND(12,10) | D8: 8 | E8: =IF(ISNUMBER(C8),IF(ABS(C8-D8)<0.000000001,"OK","FAIL"),"FAIL")
A9: ENG008 | C9: =BITOR(12,10) | D9: 14 | E9: =IF(ISNUMBER(C9),IF(ABS(C9-D9)<0.000000001,"OK","FAIL"),"FAIL")
A10: ENG009 | C10: =BITXOR(12,10) | D10: 6 | E10: =IF(ISNUMBER(C10),IF(ABS(C10-D10)<0.000000001,"OK","FAIL"),"FAIL")
A11: ENG010 | C11: =BITLSHIFT(1,4) | D11: 16 | E11: =IF(ISNUMBER(C11),IF(ABS(C11-D11)<0.000000001,"OK","FAIL"),"FAIL")
A12: ENG011 | C12: =BITRSHIFT(16,2) | D12: 4 | E12: =IF(ISNUMBER(C12),IF(ABS(C12-D12)<0.000000001,"OK","FAIL"),"FAIL")
A13: ENG012 | C13: =DELTA(5,5) | D13: 1 | E13: =IF(ISNUMBER(C13),IF(ABS(C13-D13)<0.000000001,"OK","FAIL"),"FAIL")
A14: ENG013 | C14: =DELTA(5,4) | D14: 0 | E14: =IF(ISNUMBER(C14),IF(ABS(C14-D14)<0.000000001,"OK","FAIL"),"FAIL")
A15: ENG014 | C15: =GESTEP(5,4) | D15: 1 | E15: =IF(ISNUMBER(C15),IF(ABS(C15-D15)<0.000000001,"OK","FAIL"),"FAIL")
A16: ENG015 | C16: =ERF(0) | D16: 0 | E16: =IF(ISNUMBER(C16),IF(ABS(C16-D16)<0.000000001,"OK","FAIL"),"FAIL")
A17: ENG016 | C17: =COMPLEX(3,4) | D17: 3+4i | E17: =IF(ISTEXT(C17),IF(EXACT(C17,D17),"OK","FAIL"),"FAIL")
A18: ENG017 | C18: =IMABS("3+4i") | D18: 5 | E18: =IF(ISNUMBER(C18),IF(ABS(C18-D18)<0.000000001,"OK","FAIL"),"FAIL")
A19: ENG018 | C19: =IMREAL("3+4i") | D19: 3 | E19: =IF(ISNUMBER(C19),IF(ABS(C19-D19)<0.000000001,"OK","FAIL"),"FAIL")
A20: ENG019 | C20: =IMAGINARY("3+4i") | D20: 4 | E20: =IF(ISNUMBER(C20),IF(ABS(C20-D20)<0.000000001,"OK","FAIL"),"FAIL")
A21: ENG020 | C21: =IMSUM("1+2i","3+4i") | D21: 4+6i | E21: =IF(ISTEXT(C21),IF(EXACT(C21,D21),"OK","FAIL"),"FAIL")
A22: ENG021 | C22: =CONVERT(1,"in","cm") | D22: 2.54 | E22: =IF(ISNUMBER(C22),IF(ABS(C22-D22)<0.000000001,"OK","FAIL"),"FAIL")
A23: ENG022 | C23: =CONVERT(100,"C","F") | D23: 212 | E23: =IF(ISNUMBER(C23),IF(ABS(C23-D23)<0.000000001,"OK","FAIL"),"FAIL")

Sheet Database
A1: ID | B1: Note | C1: Actual | D1: Expected | E1: Check
A2: DAT001 | B2: Qty > 8 | C2: =DSUM(Data!A1:C6,"Qty",Data!K4:K5) | D2: 45 | E2: =IF(ISNUMBER(C2),IF(ABS(C2-D2)<0.000000001,"OK","FAIL"),"FAIL")
A3: DAT002 | C3: =DCOUNT(Data!A1:C6,"Qty",Data!K4:K5) | D3: 3 | E3: =IF(ISNUMBER(C3),IF(ABS(C3-D3)<0.000000001,"OK","FAIL"),"FAIL")
A4: DAT003 | C4: =DMAX(Data!A1:C6,"Qty",Data!K4:K5) | D4: 20 | E4: =IF(ISNUMBER(C4),IF(ABS(C4-D4)<0.000000001,"OK","FAIL"),"FAIL")
A5: DAT004 | C5: =DMIN(Data!A1:C6,"Qty",Data!K4:K5) | D5: 10 | E5: =IF(ISNUMBER(C5),IF(ABS(C5-D5)<0.000000001,"OK","FAIL"),"FAIL")
A6: DAT005 | B6: Fruit = Date | C6: =DGET(Data!A1:C6,"Price",Data!L4:L5) | D6: 4.5 | E6: =IF(ISNUMBER(C6),IF(ABS(C6-D6)<0.000000001,"OK","FAIL"),"FAIL")

Sheet Errors
A1: ID | B1: Note | C1: Actual | D1: Expected | E1: Check
A2: ERR001 | B2: walks off the grid | C2: =OFFSET(Data!A1,-1,0) | D2: #REF! | E2: =IF(IFERROR(ERROR.TYPE(C2),0)=4,"OK","FAIL")
A3: ERR002 | C3: =INDIRECT("bogus ref") | D3: #REF! | E3: =IF(IFERROR(ERROR.TYPE(C3),0)=4,"OK","FAIL")
A4: ERR003 | C4: =VLOOKUP("zzz",Data!A2:C6,2,FALSE) | D4: #N/A | E4: =IF(IFERROR(ERROR.TYPE(C4),0)=7,"OK","FAIL")
A5: ERR004 | C5: =NA() | D5: #N/A | E5: =IF(IFERROR(ERROR.TYPE(C5),0)=7,"OK","FAIL")
A6: ERR005 | C6: =DATE(-1,1,1) | D6: #NUM! | E6: =IF(IFERROR(ERROR.TYPE(C6),0)=6,"OK","FAIL")
A7: ERR006 | B7: unknown function | C7: =NOSUCHFUNCTION(1) | D7: #NAME? | E7: =IF(IFERROR(ERROR.TYPE(C7),0)=5,"OK","FAIL")

Sheet Gaps
A1: ID | B1: Note | C1: Actual | D1: Expected | E1: Check
A2: GAP001 | B2: no native TRANSPOSE (MY* only) | C2: =SUM(TRANSPOSE(Data!E1:E8)) | D2: 39 | E2: =IF(ISNUMBER(C2),IF(ABS(C2-D2)<0.000000001,"OK","FAIL"),"FAIL")
A3: GAP002 | B3: no SEQUENCE | C3: =SUM(SEQUENCE(3)) | D3: 6 | E3: =IF(ISNUMBER(C3),IF(ABS(C3-D3)<0.000000001,"OK","FAIL"),"FAIL")
A4: GAP003 | B4: no LET | C4: =LET(x,2,x*3) | D4: 6 | E4: =IF(ISNUMBER(C4),IF(ABS(C4-D4)<0.000000001,"OK","FAIL"),"FAIL")
A5: GAP004 | B5: no TEXTSPLIT (anchor cell) | C5: =TEXTSPLIT("a,b",",") | D5: a | E5: =IF(ISTEXT(C5),IF(EXACT(C5,D5),"OK","FAIL"),"FAIL")
